<?xml version="1.0" encoding="utf-8"?>
<robot name="rope_chain">
  <link name="rope_seg_0">
    <inertial>
      <origin xyz="0.014063 0 0" rpy="0 0 0"/>
      <mass value="0.01104466"/>
      <inertia ixx="0.0000001381" ixy="0" ixz="0" iyy="0.0000007971" iyz="0" izz="0.0000007971"/>
    </inertial>
    <visual>
      <origin xyz="0.014063 0 0" rpy="0 1.5707963268 0"/>
      <geometry>
        <cylinder radius="0.005000" length="0.028125"/>
      </geometry>
      <material name="rope_color_0">
        <color rgba="0.0000 0.5000 0.0000 1.0000"/>
      </material>
    </visual>
    <collision>
      <origin xyz="0.014063 0 0" rpy="0 1.5707963268 0"/>
      <geometry>
        <cylinder radius="0.005000" length="0.028125"/>
      </geometry>
    </collision>
  </link>
  <link name="rope_hinge_0">
    <inertial>
      <origin xyz="0 0 0" rpy="0 0 0"/>
      <mass value="1e-6"/>
      <inertia ixx="1e-12" ixy="0" ixz="0" iyy="1e-12" iyz="0" izz="1e-12"/>
    </inertial>
    <visual>
      <origin xyz="0 0 0" rpy="0 0 0"/>
      <geometry>
        <sphere radius="0.005000"/>
      </geometry>
      <material name="hinge_color_0">
        <color rgba="0.0000 0.5000 0.0000 1.0000"/>
      </material>
    </visual>
  </link>
  <joint name="rope_pitch_0" type="revolute">
    <parent link="rope_seg_0"/>
    <child link="rope_hinge_0"/>
    <origin xyz="0.028125 0 0" rpy="0 0 0"/>
    <axis xyz="0 1 0"/>
    <limit lower="-2.094395" upper="2.094395" effort="0.1" velocity="10.0"/>
    <dynamics damping="0.5" friction="0.0"/>
  </joint>
  <joint name="rope_yaw_0" type="revolute">
    <parent link="rope_hinge_0"/>
    <child link="rope_seg_1"/>
    <origin xyz="0 0 0" rpy="0 0 0"/>
    <axis xyz="0 0 1"/>
    <limit lower="-2.094395" upper="2.094395" effort="0.1" velocity="10.0"/>
    <dynamics damping="0.5" friction="0.0"/>
  </joint>
  <link name="rope_seg_1">
    <inertial>
      <origin xyz="0.014063 0 0" rpy="0 0 0"/>
      <mass value="0.01104466"/>
      <inertia ixx="0.0000001381" ixy="0" ixz="0" iyy="0.0000007971" iyz="0" izz="0.0000007971"/>
    </inertial>
    <visual>
      <origin xyz="0.014063 0 0" rpy="0 1.5707963268 0"/>
      <geometry>
        <cylinder radius="0.005000" length="0.028125"/>
      </geometry>
      <material name="rope_color_1">
        <color rgba="0.2000 0.6000 0.0000 1.0000"/>
      </material>
    </visual>
    <collision>
      <origin xyz="0.014063 0 0" rpy="0 1.5707963268 0"/>
      <geometry>
        <cylinder radius="0.005000" length="0.028125"/>
      </geometry>
    </collision>
  </link>
  <link name="rope_hinge_1">
    <inertial>
      <origin xyz="0 0 0" rpy="0 0 0"/>
      <mass value="1e-6"/>
      <inertia ixx="1e-12" ixy="0" ixz="0" iyy="1e-12" iyz="0" izz="1e-12"/>
    </inertial>
    <visual>
      <origin xyz="0 0 0" rpy="0 0 0"/>
      <geometry>
        <sphere radius="0.005000"/>
      </geometry>
      <material name="hinge_color_1">
        <color rgba="0.2000 0.6000 0.0000 1.0000"/>
      </material>
    </visual>
  </link>
  <joint name="rope_pitch_1" type="revolute">
    <parent link="rope_seg_1"/>
    <child link="rope_hinge_1"/>
    <origin xyz="0.028125 0 0" rpy="0 0 0"/>
    <axis xyz="0 1 0"/>
    <limit lower="-2.094395" upper="2.094395" effort="0.1" velocity="10.0"/>
    <dynamics damping="0.5" friction="0.0"/>
  </joint>
  <joint name="rope_yaw_1" type="revolute">
    <parent link="rope_hinge_1"/>
    <child link="rope_seg_2"/>
    <origin xyz="0 0 0" rpy="0 0 0"/>
    <axis xyz="0 0 1"/>
    <limit lower="-2.094395" upper="2.094395" effort="0.1" velocity="10.0"/>
    <dynamics damping="0.5" friction="0.0"/>
  </joint>
  <link name="rope_seg_2">
    <inertial>
      <origin xyz="0.014063 0 0" rpy="0 0 0"/>
      <mass value="0.01104466"/>
      <inertia ixx="0.0000001381" ixy="0" ixz="0" iyy="0.0000007971" iyz="0" izz="0.0000007971"/>
    </inertial>
    <visual>
      <origin xyz="0.014063 0 0" rpy="0 1.5707963268 0"/>
      <geometry>
        <cylinder radius="0.005000" length="0.028125"/>
      </geometry>
      <material name="rope_color_2">
        <color rgba="0.4000 0.7000 0.0000 1.0000"/>
      </material>
    </visual>
    <collision>
      <origin xyz="0.014063 0 0" rpy="0 1.5707963268 0"/>
      <geometry>
        <cylinder radius="0.005000" length="0.028125"/>
      </geometry>
    </collision>
  </link>
  <link name="rope_hinge_2">
    <inertial>
      <origin xyz="0 0 0" rpy="0 0 0"/>
      <mass value="1e-6"/>
      <inertia ixx="1e-12" ixy="0" ixz="0" iyy="1e-12" iyz="0" izz="1e-12"/>
    </inertial>
    <visual>
      <origin xyz="0 0 0" rpy="0 0 0"/>
      <geometry>
        <sphere radius="0.005000"/>
      </geometry>
      <material name="hinge_color_2">
        <color rgba="0.4000 0.7000 0.0000 1.0000"/>
      </material>
    </visual>
  </link>
  <joint name="rope_pitch_2" type="revolute">
    <parent link="rope_seg_2"/>
    <child link="rope_hinge_2"/>
    <origin xyz="0.028125 0 0" rpy="0 0 0"/>
    <axis xyz="0 1 0"/>
    <limit lower="-2.094395" upper="2.094395" effort="0.1" velocity="10.0"/>
    <dynamics damping="0.5" friction="0.0"/>
  </joint>
  <joint name="rope_yaw_2" type="revolute">
    <parent link="rope_hinge_2"/>
    <child link="rope_seg_3"/>
    <origin xyz="0 0 0" rpy="0 0 0"/>
    <axis xyz="0 0 1"/>
    <limit lower="-2.094395" upper="2.094395" effort="0.1" velocity="10.0"/>
    <dynamics damping="0.5" friction="0.0"/>
  </joint>
  <link name="rope_seg_3">
    <inertial>
      <origin xyz="0.014063 0 0" rpy="0 0 0"/>
      <mass value="0.01104466"/>
      <inertia ixx="0.0000001381" ixy="0" ixz="0" iyy="0.0000007971" iyz="0" izz="0.0000007971"/>
    </inertial>
    <visual>
      <origin xyz="0.014063 0 0" rpy="0 1.5707963268 0"/>
      <geometry>
        <cylinder radius="0.005000" length="0.028125"/>
      </geometry>
      <material name="rope_color_3">
        <color rgba="0.6000 0.8000 0.0000 1.0000"/>
      </material>
    </visual>
    <collision>
      <origin xyz="0.014063 0 0" rpy="0 1.5707963268 0"/>
      <geometry>
        <cylinder radius="0.005000" length="0.028125"/>
      </geometry>
    </collision>
  </link>
  <link name="rope_hinge_3">
    <inertial>
      <origin xyz="0 0 0" rpy="0 0 0"/>
      <mass value="1e-6"/>
      <inertia ixx="1e-12" ixy="0" ixz="0" iyy="1e-12" iyz="0" izz="1e-12"/>
    </inertial>
    <visual>
      <origin xyz="0 0 0" rpy="0 0 0"/>
      <geometry>
        <sphere radius="0.005000"/>
      </geometry>
      <material name="hinge_color_3">
        <color rgba="0.6000 0.8000 0.0000 1.0000"/>
      </material>
    </visual>
  </link>
  <joint name="rope_pitch_3" type="revolute">
    <parent link="rope_seg_3"/>
    <child link="rope_hinge_3"/>
    <origin xyz="0.028125 0 0" rpy="0 0 0"/>
    <axis xyz="0 1 0"/>
    <limit lower="-2.094395" upper="2.094395" effort="0.1" velocity="10.0"/>
    <dynamics damping="0.5" friction="0.0"/>
  </joint>
  <joint name="rope_yaw_3" type="revolute">
    <parent link="rope_hinge_3"/>
    <child link="rope_seg_4"/>
    <origin xyz="0 0 0" rpy="0 0 0"/>
    <axis xyz="0 0 1"/>
    <limit lower="-2.094395" upper="2.094395" effort="0.1" velocity="10.0"/>
    <dynamics damping="0.5" friction="0.0"/>
  </joint>
  <link name="rope_seg_4">
    <inertial>
      <origin xyz="0.014063 0 0" rpy="0 0 0"/>
      <mass value="0.01104466"/>
      <inertia ixx="0.0000001381" ixy="0" ixz="0" iyy="0.0000007971" iyz="0" izz="0.0000007971"/>
    </inertial>
    <visual>
      <origin xyz="0.014063 0 0" rpy="0 1.5707963268 0"/>
      <geometry>
        <cylinder radius="0.005000" length="0.028125"/>
      </geometry>
      <material name="rope_color_4">
        <color rgba="0.8000 0.9000 0.0000 1.0000"/>
      </material>
    </visual>
    <collision>
      <origin xyz="0.014063 0 0" rpy="0 1.5707963268 0"/>
      <geometry>
        <cylinder radius="0.005000" length="0.028125"/>
      </geometry>
    </collision>
  </link>
  <link name="rope_hinge_4">
    <inertial>
      <origin xyz="0 0 0" rpy="0 0 0"/>
      <mass value="1e-6"/>
      <inertia ixx="1e-12" ixy="0" ixz="0" iyy="1e-12" iyz="0" izz="1e-12"/>
    </inertial>
    <visual>
      <origin xyz="0 0 0" rpy="0 0 0"/>
      <geometry>
        <sphere radius="0.005000"/>
      </geometry>
      <material name="hinge_color_4">
        <color rgba="0.8000 0.9000 0.0000 1.0000"/>
      </material>
    </visual>
  </link>
  <joint name="rope_pitch_4" type="revolute">
    <parent link="rope_seg_4"/>
    <child link="rope_hinge_4"/>
    <origin xyz="0.028125 0 0" rpy="0 0 0"/>
    <axis xyz="0 1 0"/>
    <limit lower="-2.094395" upper="2.094395" effort="0.1" velocity="10.0"/>
    <dynamics damping="0.5" friction="0.0"/>
  </joint>
  <joint name="rope_yaw_4" type="revolute">
    <parent link="rope_hinge_4"/>
    <child link="rope_seg_5"/>
    <origin xyz="0 0 0" rpy="0 0 0"/>
    <axis xyz="0 0 1"/>
    <limit lower="-2.094395" upper="2.094395" effort="0.1" velocity="10.0"/>
    <dynamics damping="0.5" friction="0.0"/>
  </joint>
  <link name="rope_seg_5">
    <inertial>
      <origin xyz="0.014063 0 0" rpy="0 0 0"/>
      <mass value="0.01104466"/>
      <inertia ixx="0.0000001381" ixy="0" ixz="0" iyy="0.0000007971" iyz="0" izz="0.0000007971"/>
    </inertial>
    <visual>
      <origin xyz="0.014063 0 0" rpy="0 1.5707963268 0"/>
      <geometry>
        <cylinder radius="0.005000" length="0.028125"/>
      </geometry>
      <material name="rope_color_5">
        <color rgba="1.0000 1.0000 0.0000 1.0000"/>
      </material>
    </visual>
    <collision>
      <origin xyz="0.014063 0 0" rpy="0 1.5707963268 0"/>
      <geometry>
        <cylinder radius="0.005000" length="0.028125"/>
      </geometry>
    </collision>
  </link>
  <link name="rope_hinge_5">
    <inertial>
      <origin xyz="0 0 0" rpy="0 0 0"/>
      <mass value="1e-6"/>
      <inertia ixx="1e-12" ixy="0" ixz="0" iyy="1e-12" iyz="0" izz="1e-12"/>
    </inertial>
    <visual>
      <origin xyz="0 0 0" rpy="0 0 0"/>
      <geometry>
        <sphere radius="0.005000"/>
      </geometry>
      <material name="hinge_color_5">
        <color rgba="1.0000 1.0000 0.0000 1.0000"/>
      </material>
    </visual>
  </link>
  <joint name="rope_pitch_5" type="revolute">
    <parent link="rope_seg_5"/>
    <child link="rope_hinge_5"/>
    <origin xyz="0.028125 0 0" rpy="0 0 0"/>
    <axis xyz="0 1 0"/>
    <limit lower="-2.094395" upper="2.094395" effort="0.1" velocity="10.0"/>
    <dynamics damping="0.5" friction="0.0"/>
  </joint>
  <joint name="rope_yaw_5" type="revolute">
    <parent link="rope_hinge_5"/>
    <child link="rope_seg_6"/>
    <origin xyz="0 0 0" rpy="0 0 0"/>
    <axis xyz="0 0 1"/>
    <limit lower="-2.094395" upper="2.094395" effort="0.1" velocity="10.0"/>
    <dynamics damping="0.5" friction="0.0"/>
  </joint>
  <link name="rope_seg_6">
    <inertial>
      <origin xyz="0.014063 0 0" rpy="0 0 0"/>
      <mass value="0.01104466"/>
      <inertia ixx="0.0000001381" ixy="0" ixz="0" iyy="0.0000007971" iyz="0" izz="0.0000007971"/>
    </inertial>
    <visual>
      <origin xyz="0.014063 0 0" rpy="0 1.5707963268 0"/>
      <geometry>
        <cylinder radius="0.005000" length="0.028125"/>
      </geometry>
      <material name="rope_color_6">
        <color rgba="1.0000 0.8000 0.0000 1.0000"/>
      </material>
    </visual>
    <collision>
      <origin xyz="0.014063 0 0" rpy="0 1.5707963268 0"/>
      <geometry>
        <cylinder radius="0.005000" length="0.028125"/>
      </geometry>
    </collision>
  </link>
  <link name="rope_hinge_6">
    <inertial>
      <origin xyz="0 0 0" rpy="0 0 0"/>
      <mass value="1e-6"/>
      <inertia ixx="1e-12" ixy="0" ixz="0" iyy="1e-12" iyz="0" izz="1e-12"/>
    </inertial>
    <visual>
      <origin xyz="0 0 0" rpy="0 0 0"/>
      <geometry>
        <sphere radius="0.005000"/>
      </geometry>
      <material name="hinge_color_6">
        <color rgba="1.0000 0.8000 0.0000 1.0000"/>
      </material>
    </visual>
  </link>
  <joint name="rope_pitch_6" type="revolute">
    <parent link="rope_seg_6"/>
    <child link="rope_hinge_6"/>
    <origin xyz="0.028125 0 0" rpy="0 0 0"/>
    <axis xyz="0 1 0"/>
    <limit lower="-2.094395" upper="2.094395" effort="0.1" velocity="10.0"/>
    <dynamics damping="0.5" friction="0.0"/>
  </joint>
  <joint name="rope_yaw_6" type="revolute">
    <parent link="rope_hinge_6"/>
    <child link="rope_seg_7"/>
    <origin xyz="0 0 0" rpy="0 0 0"/>
    <axis xyz="0 0 1"/>
    <limit lower="-2.094395" upper="2.094395" effort="0.1" velocity="10.0"/>
    <dynamics damping="0.5" friction="0.0"/>
  </joint>
  <link name="rope_seg_7">
    <inertial>
      <origin xyz="0.014063 0 0" rpy="0 0 0"/>
      <mass value="0.01104466"/>
      <inertia ixx="0.0000001381" ixy="0" ixz="0" iyy="0.0000007971" iyz="0" izz="0.0000007971"/>
    </inertial>
    <visual>
      <origin xyz="0.014063 0 0" rpy="0 1.5707963268 0"/>
      <geometry>
        <cylinder radius="0.005000" length="0.028125"/>
      </geometry>
      <material name="rope_color_7">
        <color rgba="1.0000 0.6000 0.0000 1.0000"/>
      </material>
    </visual>
    <collision>
      <origin xyz="0.014063 0 0" rpy="0 1.5707963268 0"/>
      <geometry>
        <cylinder radius="0.005000" length="0.028125"/>
      </geometry>
    </collision>
  </link>
  <link name="rope_hinge_7">
    <inertial>
      <origin xyz="0 0 0" rpy="0 0 0"/>
      <mass value="1e-6"/>
      <inertia ixx="1e-12" ixy="0" ixz="0" iyy="1e-12" iyz="0" izz="1e-12"/>
    </inertial>
    <visual>
      <origin xyz="0 0 0" rpy="0 0 0"/>
      <geometry>
        <sphere radius="0.005000"/>
      </geometry>
      <material name="hinge_color_7">
        <color rgba="1.0000 0.6000 0.0000 1.0000"/>
      </material>
    </visual>
  </link>
  <joint name="rope_pitch_7" type="revolute">
    <parent link="rope_seg_7"/>
    <child link="rope_hinge_7"/>
    <origin xyz="0.028125 0 0" rpy="0 0 0"/>
    <axis xyz="0 1 0"/>
    <limit lower="-2.094395" upper="2.094395" effort="0.1" velocity="10.0"/>
    <dynamics damping="0.5" friction="0.0"/>
  </joint>
  <joint name="rope_yaw_7" type="revolute">
    <parent link="rope_hinge_7"/>
    <child link="rope_seg_8"/>
    <origin xyz="0 0 0" rpy="0 0 0"/>
    <axis xyz="0 0 1"/>
    <limit lower="-2.094395" upper="2.094395" effort="0.1" velocity="10.0"/>
    <dynamics damping="0.5" friction="0.0"/>
  </joint>
  <link name="rope_seg_8">
    <inertial>
      <origin xyz="0.014063 0 0" rpy="0 0 0"/>
      <mass value="0.01104466"/>
      <inertia ixx="0.0000001381" ixy="0" ixz="0" iyy="0.0000007971" iyz="0" izz="0.0000007971"/>
    </inertial>
    <visual>
      <origin xyz="0.014063 0 0" rpy="0 1.5707963268 0"/>
      <geometry>
        <cylinder radius="0.005000" length="0.028125"/>
      </geometry>
      <material name="rope_color_8">
        <color rgba="1.0000 0.4000 0.0000 1.0000"/>
      </material>
    </visual>
    <collision>
      <origin xyz="0.014063 0 0" rpy="0 1.5707963268 0"/>
      <geometry>
        <cylinder radius="0.005000" length="0.028125"/>
      </geometry>
    </collision>
  </link>
  <link name="rope_hinge_8">
    <inertial>
      <origin xyz="0 0 0" rpy="0 0 0"/>
      <mass value="1e-6"/>
      <inertia ixx="1e-12" ixy="0" ixz="0" iyy="1e-12" iyz="0" izz="1e-12"/>
    </inertial>
    <visual>
      <origin xyz="0 0 0" rpy="0 0 0"/>
      <geometry>
        <sphere radius="0.005000"/>
      </geometry>
      <material name="hinge_color_8">
        <color rgba="1.0000 0.4000 0.0000 1.0000"/>
      </material>
    </visual>
  </link>
  <joint name="rope_pitch_8" type="revolute">
    <parent link="rope_seg_8"/>
    <child link="rope_hinge_8"/>
    <origin xyz="0.028125 0 0" rpy="0 0 0"/>
    <axis xyz="0 1 0"/>
    <limit lower="-2.094395" upper="2.094395" effort="0.1" velocity="10.0"/>
    <dynamics damping="0.5" friction="0.0"/>
  </joint>
  <joint name="rope_yaw_8" type="revolute">
    <parent link="rope_hinge_8"/>
    <child link="rope_seg_9"/>
    <origin xyz="0 0 0" rpy="0 0 0"/>
    <axis xyz="0 0 1"/>
    <limit lower="-2.094395" upper="2.094395" effort="0.1" velocity="10.0"/>
    <dynamics damping="0.5" friction="0.0"/>
  </joint>
  <link name="rope_seg_9">
    <inertial>
      <origin xyz="0.014063 0 0" rpy="0 0 0"/>
      <mass value="0.01104466"/>
      <inertia ixx="0.0000001381" ixy="0" ixz="0" iyy="0.0000007971" iyz="0" izz="0.0000007971"/>
    </inertial>
    <visual>
      <origin xyz="0.014063 0 0" rpy="0 1.5707963268 0"/>
      <geometry>
        <cylinder radius="0.005000" length="0.028125"/>
      </geometry>
      <material name="rope_color_9">
        <color rgba="1.0000 0.2000 0.0000 1.0000"/>
      </material>
    </visual>
    <collision>
      <origin xyz="0.014063 0 0" rpy="0 1.5707963268 0"/>
      <geometry>
        <cylinder radius="0.005000" length="0.028125"/>
      </geometry>
    </collision>
  </link>
  <link name="rope_hinge_9">
    <inertial>
      <origin xyz="0 0 0" rpy="0 0 0"/>
      <mass value="1e-6"/>
      <inertia ixx="1e-12" ixy="0" ixz="0" iyy="1e-12" iyz="0" izz="1e-12"/>
    </inertial>
    <visual>
      <origin xyz="0 0 0" rpy="0 0 0"/>
      <geometry>
        <sphere radius="0.005000"/>
      </geometry>
      <material name="hinge_color_9">
        <color rgba="1.0000 0.2000 0.0000 1.0000"/>
      </material>
    </visual>
  </link>
  <joint name="rope_pitch_9" type="revolute">
    <parent link="rope_seg_9"/>
    <child link="rope_hinge_9"/>
    <origin xyz="0.028125 0 0" rpy="0 0 0"/>
    <axis xyz="0 1 0"/>
    <limit lower="-2.094395" upper="2.094395" effort="0.1" velocity="10.0"/>
    <dynamics damping="0.5" friction="0.0"/>
  </joint>
  <joint name="rope_yaw_9" type="revolute">
    <parent link="rope_hinge_9"/>
    <child link="rope_seg_10"/>
    <origin xyz="0 0 0" rpy="0 0 0"/>
    <axis xyz="0 0 1"/>
    <limit lower="-2.094395" upper="2.094395" effort="0.1" velocity="10.0"/>
    <dynamics damping="0.5" friction="0.0"/>
  </joint>
  <link name="rope_seg_10">
    <inertial>
      <origin xyz="0.014063 0 0" rpy="0 0 0"/>
      <mass value="0.01104466"/>
      <inertia ixx="0.0000001381" ixy="0" ixz="0" iyy="0.0000007971" iyz="0" izz="0.0000007971"/>
    </inertial>
    <visual>
      <origin xyz="0.014063 0 0" rpy="0 1.5707963268 0"/>
      <geometry>
        <cylinder radius="0.005000" length="0.028125"/>
      </geometry>
      <material name="rope_color_10">
        <color rgba="1.0000 0.0000 0.0000 1.0000"/>
      </material>
    </visual>
    <collision>
      <origin xyz="0.014063 0 0" rpy="0 1.5707963268 0"/>
      <geometry>
        <cylinder radius="0.005000" length="0.028125"/>
      </geometry>
    </collision>
  </link>
  <link name="rope_hinge_10">
    <inertial>
      <origin xyz="0 0 0" rpy="0 0 0"/>
      <mass value="1e-6"/>
      <inertia ixx="1e-12" ixy="0" ixz="0" iyy="1e-12" iyz="0" izz="1e-12"/>
    </inertial>
    <visual>
      <origin xyz="0 0 0" rpy="0 0 0"/>
      <geometry>
        <sphere radius="0.005000"/>
      </geometry>
      <material name="hinge_color_10">
        <color rgba="1.0000 0.0000 0.0000 1.0000"/>
      </material>
    </visual>
  </link>
  <joint name="rope_pitch_10" type="revolute">
    <parent link="rope_seg_10"/>
    <child link="rope_hinge_10"/>
    <origin xyz="0.028125 0 0" rpy="0 0 0"/>
    <axis xyz="0 1 0"/>
    <limit lower="-2.094395" upper="2.094395" effort="0.1" velocity="10.0"/>
    <dynamics damping="0.5" friction="0.0"/>
  </joint>
  <joint name="rope_yaw_10" type="revolute">
    <parent link="rope_hinge_10"/>
    <child link="rope_seg_11"/>
    <origin xyz="0 0 0" rpy="0 0 0"/>
    <axis xyz="0 0 1"/>
    <limit lower="-2.094395" upper="2.094395" effort="0.1" velocity="10.0"/>
    <dynamics damping="0.5" friction="0.0"/>
  </joint>
  <link name="rope_seg_11">
    <inertial>
      <origin xyz="0.014063 0 0" rpy="0 0 0"/>
      <mass value="0.01104466"/>
      <inertia ixx="0.0000001381" ixy="0" ixz="0" iyy="0.0000007971" iyz="0" izz="0.0000007971"/>
    </inertial>
    <visual>
      <origin xyz="0.014063 0 0" rpy="0 1.5707963268 0"/>
      <geometry>
        <cylinder radius="0.005000" length="0.028125"/>
      </geometry>
      <material name="rope_color_11">
        <color rgba="0.8000 0.0000 0.2000 1.0000"/>
      </material>
    </visual>
    <collision>
      <origin xyz="0.014063 0 0" rpy="0 1.5707963268 0"/>
      <geometry>
        <cylinder radius="0.005000" length="0.028125"/>
      </geometry>
    </collision>
  </link>
  <link name="rope_hinge_11">
    <inertial>
      <origin xyz="0 0 0" rpy="0 0 0"/>
      <mass value="1e-6"/>
      <inertia ixx="1e-12" ixy="0" ixz="0" iyy="1e-12" iyz="0" izz="1e-12"/>
    </inertial>
    <visual>
      <origin xyz="0 0 0" rpy="0 0 0"/>
      <geometry>
        <sphere radius="0.005000"/>
      </geometry>
      <material name="hinge_color_11">
        <color rgba="0.8000 0.0000 0.2000 1.0000"/>
      </material>
    </visual>
  </link>
  <joint name="rope_pitch_11" type="revolute">
    <parent link="rope_seg_11"/>
    <child link="rope_hinge_11"/>
    <origin xyz="0.028125 0 0" rpy="0 0 0"/>
    <axis xyz="0 1 0"/>
    <limit lower="-2.094395" upper="2.094395" effort="0.1" velocity="10.0"/>
    <dynamics damping="0.5" friction="0.0"/>
  </joint>
  <joint name="rope_yaw_11" type="revolute">
    <parent link="rope_hinge_11"/>
    <child link="rope_seg_12"/>
    <origin xyz="0 0 0" rpy="0 0 0"/>
    <axis xyz="0 0 1"/>
    <limit lower="-2.094395" upper="2.094395" effort="0.1" velocity="10.0"/>
    <dynamics damping="0.5" friction="0.0"/>
  </joint>
  <link name="rope_seg_12">
    <inertial>
      <origin xyz="0.014063 0 0" rpy="0 0 0"/>
      <mass value="0.01104466"/>
      <inertia ixx="0.0000001381" ixy="0" ixz="0" iyy="0.0000007971" iyz="0" izz="0.0000007971"/>
    </inertial>
    <visual>
      <origin xyz="0.014063 0 0" rpy="0 1.5707963268 0"/>
      <geometry>
        <cylinder radius="0.005000" length="0.028125"/>
      </geometry>
      <material name="rope_color_12">
        <color rgba="0.6000 0.0000 0.4000 1.0000"/>
      </material>
    </visual>
    <collision>
      <origin xyz="0.014063 0 0" rpy="0 1.5707963268 0"/>
      <geometry>
        <cylinder radius="0.005000" length="0.028125"/>
      </geometry>
    </collision>
  </link>
  <link name="rope_hinge_12">
    <inertial>
      <origin xyz="0 0 0" rpy="0 0 0"/>
      <mass value="1e-6"/>
      <inertia ixx="1e-12" ixy="0" ixz="0" iyy="1e-12" iyz="0" izz="1e-12"/>
    </inertial>
    <visual>
      <origin xyz="0 0 0" rpy="0 0 0"/>
      <geometry>
        <sphere radius="0.005000"/>
      </geometry>
      <material name="hinge_color_12">
        <color rgba="0.6000 0.0000 0.4000 1.0000"/>
      </material>
    </visual>
  </link>
  <joint name="rope_pitch_12" type="revolute">
    <parent link="rope_seg_12"/>
    <child link="rope_hinge_12"/>
    <origin xyz="0.028125 0 0" rpy="0 0 0"/>
    <axis xyz="0 1 0"/>
    <limit lower="-2.094395" upper="2.094395" effort="0.1" velocity="10.0"/>
    <dynamics damping="0.5" friction="0.0"/>
  </joint>
  <joint name="rope_yaw_12" type="revolute">
    <parent link="rope_hinge_12"/>
    <child link="rope_seg_13"/>
    <origin xyz="0 0 0" rpy="0 0 0"/>
    <axis xyz="0 0 1"/>
    <limit lower="-2.094395" upper="2.094395" effort="0.1" velocity="10.0"/>
    <dynamics damping="0.5" friction="0.0"/>
  </joint>
  <link name="rope_seg_13">
    <inertial>
      <origin xyz="0.014063 0 0" rpy="0 0 0"/>
      <mass value="0.01104466"/>
      <inertia ixx="0.0000001381" ixy="0" ixz="0" iyy="0.0000007971" iyz="0" izz="0.0000007971"/>
    </inertial>
    <visual>
      <origin xyz="0.014063 0 0" rpy="0 1.5707963268 0"/>
      <geometry>
        <cylinder radius="0.005000" length="0.028125"/>
      </geometry>
      <material name="rope_color_13">
        <color rgba="0.4000 0.0000 0.6000 1.0000"/>
      </material>
    </visual>
    <collision>
      <origin xyz="0.014063 0 0" rpy="0 1.5707963268 0"/>
      <geometry>
        <cylinder radius="0.005000" length="0.028125"/>
      </geometry>
    </collision>
  </link>
  <link name="rope_hinge_13">
    <inertial>
      <origin xyz="0 0 0" rpy="0 0 0"/>
      <mass value="1e-6"/>
      <inertia ixx="1e-12" ixy="0" ixz="0" iyy="1e-12" iyz="0" izz="1e-12"/>
    </inertial>
    <visual>
      <origin xyz="0 0 0" rpy="0 0 0"/>
      <geometry>
        <sphere radius="0.005000"/>
      </geometry>
      <material name="hinge_color_13">
        <color rgba="0.4000 0.0000 0.6000 1.0000"/>
      </material>
    </visual>
  </link>
  <joint name="rope_pitch_13" type="revolute">
    <parent link="rope_seg_13"/>
    <child link="rope_hinge_13"/>
    <origin xyz="0.028125 0 0" rpy="0 0 0"/>
    <axis xyz="0 1 0"/>
    <limit lower="-2.094395" upper="2.094395" effort="0.1" velocity="10.0"/>
    <dynamics damping="0.5" friction="0.0"/>
  </joint>
  <joint name="rope_yaw_13" type="revolute">
    <parent link="rope_hinge_13"/>
    <child link="rope_seg_14"/>
    <origin xyz="0 0 0" rpy="0 0 0"/>
    <axis xyz="0 0 1"/>
    <limit lower="-2.094395" upper="2.094395" effort="0.1" velocity="10.0"/>
    <dynamics damping="0.5" friction="0.0"/>
  </joint>
  <link name="rope_seg_14">
    <inertial>
      <origin xyz="0.014063 0 0" rpy="0 0 0"/>
      <mass value="0.01104466"/>
      <inertia ixx="0.0000001381" ixy="0" ixz="0" iyy="0.0000007971" iyz="0" izz="0.0000007971"/>
    </inertial>
    <visual>
      <origin xyz="0.014063 0 0" rpy="0 1.5707963268 0"/>
      <geometry>
        <cylinder radius="0.005000" length="0.028125"/>
      </geometry>
      <material name="rope_color_14">
        <color rgba="0.2000 0.0000 0.8000 1.0000"/>
      </material>
    </visual>
    <collision>
      <origin xyz="0.014063 0 0" rpy="0 1.5707963268 0"/>
      <geometry>
        <cylinder radius="0.005000" length="0.028125"/>
      </geometry>
    </collision>
  </link>
  <link name="rope_hinge_14">
    <inertial>
      <origin xyz="0 0 0" rpy="0 0 0"/>
      <mass value="1e-6"/>
      <inertia ixx="1e-12" ixy="0" ixz="0" iyy="1e-12" iyz="0" izz="1e-12"/>
    </inertial>
    <visual>
      <origin xyz="0 0 0" rpy="0 0 0"/>
      <geometry>
        <sphere radius="0.005000"/>
      </geometry>
      <material name="hinge_color_14">
        <color rgba="0.2000 0.0000 0.8000 1.0000"/>
      </material>
    </visual>
  </link>
  <joint name="rope_pitch_14" type="revolute">
    <parent link="rope_seg_14"/>
    <child link="rope_hinge_14"/>
    <origin xyz="0.028125 0 0" rpy="0 0 0"/>
    <axis xyz="0 1 0"/>
    <limit lower="-2.094395" upper="2.094395" effort="0.1" velocity="10.0"/>
    <dynamics damping="0.5" friction="0.0"/>
  </joint>
  <joint name="rope_yaw_14" type="revolute">
    <parent link="rope_hinge_14"/>
    <child link="rope_seg_15"/>
    <origin xyz="0 0 0" rpy="0 0 0"/>
    <axis xyz="0 0 1"/>
    <limit lower="-2.094395" upper="2.094395" effort="0.1" velocity="10.0"/>
    <dynamics damping="0.5" friction="0.0"/>
  </joint>
  <link name="rope_seg_15">
    <inertial>
      <origin xyz="0.014063 0 0" rpy="0 0 0"/>
      <mass value="0.01104466"/>
      <inertia ixx="0.0000001381" ixy="0" ixz="0" iyy="0.0000007971" iyz="0" izz="0.0000007971"/>
    </inertial>
    <visual>
      <origin xyz="0.014063 0 0" rpy="0 1.5707963268 0"/>
      <geometry>
        <cylinder radius="0.005000" length="0.028125"/>
      </geometry>
      <material name="rope_color_15">
        <color rgba="0.0000 0.0000 1.0000 1.0000"/>
      </material>
    </visual>
    <collision>
      <origin xyz="0.014063 0 0" rpy="0 1.5707963268 0"/>
      <geometry>
        <cylinder radius="0.005000" length="0.028125"/>
      </geometry>
    </collision>
  </link>
</robot>
